2018-04-11 16:25:57,329 INFO: Microblog statup [in /Users/joseph/Documents/playground/flask-app/app/__init__.py:30]
2018-04-11 16:26:26,324 INFO: Microblog statup [in /Users/joseph/Documents/playground/flask-app/app/__init__.py:30]
2018-04-11 16:26:28,670 ERROR: Exception on /robots.txt [GET] [in /Users/joseph/anaconda3/lib/python3.6/site-packages/flask/app.py:1560]
Traceback (most recent call last):
  File "/Users/joseph/anaconda3/lib/python3.6/site-packages/flask/app.py", line 1612, in full_dispatch_request
    rv = self.dispatch_request()
  File "/Users/joseph/anaconda3/lib/python3.6/site-packages/flask/app.py", line 1590, in dispatch_request
    self.raise_routing_exception(req)
  File "/Users/joseph/anaconda3/lib/python3.6/site-packages/flask/app.py", line 1573, in raise_routing_exception
    raise request.routing_exception
  File "/Users/joseph/anaconda3/lib/python3.6/site-packages/flask/ctx.py", line 294, in match_request
    self.url_adapter.match(return_rule=True)
  File "/Users/joseph/anaconda3/lib/python3.6/site-packages/werkzeug/routing.py", line 1573, in match
    raise NotFound()
werkzeug.exceptions.NotFound: 404 Not Found: The requested URL was not found on the server.  If you entered the URL manually please check your spelling and try again.

During handling of the above exception, another exception occurred:

Traceback (most recent call last):
  File "/Users/joseph/anaconda3/lib/python3.6/site-packages/flask/app.py", line 1982, in wsgi_app
    response = self.full_dispatch_request()
  File "/Users/joseph/anaconda3/lib/python3.6/site-packages/flask/app.py", line 1614, in full_dispatch_request
    rv = self.handle_user_exception(e)
  File "/Users/joseph/anaconda3/lib/python3.6/site-packages/flask/app.py", line 1512, in handle_user_exception
    return self.handle_http_exception(e)
  File "/Users/joseph/anaconda3/lib/python3.6/site-packages/flask/app.py", line 1471, in handle_http_exception
    return handler(e)
  File "/Users/joseph/Documents/playground/flask-app/app/errors.py", line 6, in not_found_error
    return render_tempalte('404.html'), 404
NameError: name 'render_tempalte' is not defined
2018-04-11 16:27:15,987 INFO: Microblog statup [in /Users/joseph/Documents/playground/flask-app/app/__init__.py:30]
2018-04-17 13:30:18,069 INFO: Microblog statup [in /Users/joseph/Documents/playground/flask-app/app/__init__.py:30]
2018-04-17 13:40:06,923 INFO: Microblog statup [in /Users/joseph/Documents/playground/flask-app/app/__init__.py:30]
2018-04-17 13:40:17,938 INFO: Microblog statup [in /Users/joseph/Documents/playground/flask-app/app/__init__.py:30]
2019-04-02 20:16:58,291 INFO: Microblog statup [in /Users/josephhaaga/Documents/flask-app/app/__init__.py:30]
2019-04-02 21:23:29,854 INFO: Microblog statup [in /Users/josephhaaga/Documents/flask-app/app/__init__.py:31]
2019-04-02 21:31:44,760 INFO: Microblog statup [in /Users/josephhaaga/Documents/flask-app/app/__init__.py:31]
2019-04-02 21:34:45,936 INFO: Microblog statup [in /Users/josephhaaga/Documents/flask-app/app/__init__.py:31]
2019-04-02 21:35:29,660 INFO: Microblog statup [in /Users/josephhaaga/Documents/flask-app/app/__init__.py:31]
2019-04-02 21:35:44,961 INFO: Microblog statup [in /Users/josephhaaga/Documents/flask-app/app/__init__.py:31]
2019-04-02 21:35:50,305 INFO: Microblog statup [in /Users/josephhaaga/Documents/flask-app/app/__init__.py:31]
2019-04-02 21:36:05,895 INFO: Microblog statup [in /Users/josephhaaga/Documents/flask-app/app/__init__.py:31]
2019-04-02 21:38:42,433 INFO: Microblog statup [in /Users/josephhaaga/Documents/flask-app/app/__init__.py:31]
2019-04-02 21:39:13,733 INFO: Microblog statup [in /Users/josephhaaga/Documents/flask-app/app/__init__.py:31]
2019-04-02 21:42:26,331 INFO: Microblog statup [in /Users/josephhaaga/Documents/flask-app/app/__init__.py:31]
2019-04-13 22:06:58,636 INFO: Microblog statup [in /Users/josephhaaga/Documents/flask-app/app/__init__.py:31]
2019-04-13 22:22:25,581 INFO: Microblog statup [in /Users/josephhaaga/Documents/flask-app/app/__init__.py:31]
2019-04-23 17:24:51,722 INFO: Microblog statup [in /Users/josephhaaga/Documents/flask-app/app/__init__.py:31]
